## limit handler ##
Traceback (most recent call last):
  File "/home/ggapp/.local/lib/python3.5/site-packages/urllib3/connectionpool.py", line 600, in urlopen
    chunked=chunked)
  File "/home/ggapp/.local/lib/python3.5/site-packages/urllib3/connectionpool.py", line 384, in _make_request
    six.raise_from(e, None)
  File "<string>", line 2, in raise_from
  File "/home/ggapp/.local/lib/python3.5/site-packages/urllib3/connectionpool.py", line 380, in _make_request
    httplib_response = conn.getresponse()
  File "/usr/lib/python3.5/http/client.py", line 1197, in getresponse
    response.begin()
  File "/usr/lib/python3.5/http/client.py", line 297, in begin
    version, status, reason = self._read_status()
  File "/usr/lib/python3.5/http/client.py", line 258, in _read_status
    line = str(self.fp.readline(_MAXLINE + 1), "iso-8859-1")
  File "/usr/lib/python3.5/socket.py", line 575, in readinto
    return self._sock.recv_into(b)
  File "/usr/lib/python3.5/ssl.py", line 929, in recv_into
    return self.read(nbytes, buffer)
  File "/usr/lib/python3.5/ssl.py", line 791, in read
    return self._sslobj.read(len, buffer)
  File "/usr/lib/python3.5/ssl.py", line 575, in read
    v = self._sslobj.read(len, buffer)
ConnectionResetError: [Errno 104] Connection reset by peer

During handling of the above exception, another exception occurred:

Traceback (most recent call last):
  File "/home/ggapp/.local/lib/python3.5/site-packages/requests/adapters.py", line 449, in send
    timeout=timeout
  File "/home/ggapp/.local/lib/python3.5/site-packages/urllib3/connectionpool.py", line 638, in urlopen
    _stacktrace=sys.exc_info()[2])
  File "/home/ggapp/.local/lib/python3.5/site-packages/urllib3/util/retry.py", line 367, in increment
    raise six.reraise(type(error), error, _stacktrace)
  File "/home/ggapp/.local/lib/python3.5/site-packages/urllib3/packages/six.py", line 685, in reraise
    raise value.with_traceback(tb)
  File "/home/ggapp/.local/lib/python3.5/site-packages/urllib3/connectionpool.py", line 600, in urlopen
    chunked=chunked)
  File "/home/ggapp/.local/lib/python3.5/site-packages/urllib3/connectionpool.py", line 384, in _make_request
    six.raise_from(e, None)
  File "<string>", line 2, in raise_from
  File "/home/ggapp/.local/lib/python3.5/site-packages/urllib3/connectionpool.py", line 380, in _make_request
    httplib_response = conn.getresponse()
  File "/usr/lib/python3.5/http/client.py", line 1197, in getresponse
    response.begin()
  File "/usr/lib/python3.5/http/client.py", line 297, in begin
    version, status, reason = self._read_status()
  File "/usr/lib/python3.5/http/client.py", line 258, in _read_status
    line = str(self.fp.readline(_MAXLINE + 1), "iso-8859-1")
  File "/usr/lib/python3.5/socket.py", line 575, in readinto
    return self._sock.recv_into(b)
  File "/usr/lib/python3.5/ssl.py", line 929, in recv_into
    return self.read(nbytes, buffer)
  File "/usr/lib/python3.5/ssl.py", line 791, in read
    return self._sslobj.read(len, buffer)
  File "/usr/lib/python3.5/ssl.py", line 575, in read
    v = self._sslobj.read(len, buffer)
urllib3.exceptions.ProtocolError: ('Connection aborted.', ConnectionResetError(104, 'Connection reset by peer'))

During handling of the above exception, another exception occurred:

Traceback (most recent call last):
  File "/home/ggapp/.local/lib/python3.5/site-packages/tweepy/binder.py", line 190, in execute
    proxies=self.api.proxy)
  File "/home/ggapp/.local/lib/python3.5/site-packages/requests/sessions.py", line 524, in request
    resp = self.send(prep, **send_kwargs)
  File "/home/ggapp/.local/lib/python3.5/site-packages/requests/sessions.py", line 637, in send
    r = adapter.send(request, **kwargs)
  File "/home/ggapp/.local/lib/python3.5/site-packages/requests/adapters.py", line 498, in send
    raise ConnectionError(err, request=request)
requests.exceptions.ConnectionError: ('Connection aborted.', ConnectionResetError(104, 'Connection reset by peer'))

During handling of the above exception, another exception occurred:

Traceback (most recent call last):
  File "/home/ggapp/botsanalysis/data.py", line 57, in get_followers
    page = next(pages)
  File "/home/ggapp/botsanalysis/data.py", line 27, in limit_handler
    yield cursor.next()
  File "/home/ggapp/.local/lib/python3.5/site-packages/tweepy/cursor.py", line 197, in next
    self.current_page = self.page_iterator.next()
  File "/home/ggapp/.local/lib/python3.5/site-packages/tweepy/cursor.py", line 75, in next
    **self.kargs)
  File "/home/ggapp/.local/lib/python3.5/site-packages/tweepy/binder.py", line 250, in _call
    return method.execute()
  File "/home/ggapp/.local/lib/python3.5/site-packages/tweepy/binder.py", line 192, in execute
    six.reraise(TweepError, TweepError('Failed to send request: %s' % e), sys.exc_info()[2])
  File "/home/ggapp/.local/lib/python3.5/site-packages/six.py", line 692, in reraise
    raise value.with_traceback(tb)
  File "/home/ggapp/.local/lib/python3.5/site-packages/tweepy/binder.py", line 190, in execute
    proxies=self.api.proxy)
  File "/home/ggapp/.local/lib/python3.5/site-packages/requests/sessions.py", line 524, in request
    resp = self.send(prep, **send_kwargs)
  File "/home/ggapp/.local/lib/python3.5/site-packages/requests/sessions.py", line 637, in send
    r = adapter.send(request, **kwargs)
  File "/home/ggapp/.local/lib/python3.5/site-packages/requests/adapters.py", line 498, in send
    raise ConnectionError(err, request=request)
tweepy.error.TweepError: Failed to send request: ('Connection aborted.', ConnectionResetError(104, 'Connection reset by peer'))

During handling of the above exception, another exception occurred:

Traceback (most recent call last):
  File "user_crawler.py", line 44, in <module>
    followers = data.get_followers(user_id, api)
  File "/home/ggapp/botsanalysis/data.py", line 63, in get_followers
    page = next(pages)
StopIteration
